Workbook

Sheet Team Outlook
A1: WCS ANALYTICS — TONIGHT'S SCORING OUTLOOK
A2: ="Slate: "&TEXT('Line Stats'!B3,"@")&" | Updates automatically from the Line Stats tab | GOLD = HIGH scoring chance" -> Slate: 46302 | Updates automatically from the Line Stats tab | GOLD = HIGH scoring chance
A4: TOP 3 LINES MOST LIKELY TO SCORE TONIGHT
A5: # | B5: Team | C5: Line | D5: Opponent | E5: Scoring Index | F5: Tier | G5: Why
A6: 1 | B6: =IFERROR(INDEX('Line Stats'!$A$6:$A$69,MATCH(LARGE('Line Stats'!$X$6:$X$69,1),'Line Stats'!$X$6:$X$69,0)),"") -> Avalanche | C6: =IFERROR(INDEX('Line Stats'!$C$6:$C$69,MATCH(LARGE('Line Stats'!$X$6:$X$69,1),'Line Stats'!$X$6:$X$69,0)),"") -> FL1 | D6: =IFERROR(INDEX('Line Stats'!$B$6:$B$69,MATCH(LARGE('Line Stats'!$X$6:$X$69,1),'Line Stats'!$X$6:$X$69,0)),"") -> Jets | E6: =IFERROR(INDEX('Line Stats'!$S$6:$S$69,MATCH(LARGE('Line Stats'!$X$6:$X$69,1),'Line Stats'!$X$6:$X$69,0)),"") -> 87.8 | F6: =IFERROR(INDEX('Line Stats'!$T$6:$T$69,MATCH(LARGE('Line Stats'!$X$6:$X$69,1),'Line Stats'!$X$6:$X$69,0)),"") -> HIGH | G6: =IFERROR(INDEX('Line Stats'!$V$6:$V$69,MATCH(LARGE('Line Stats'!$X$6:$X$69,1),'Line Stats'!$X$6:$X$69,0)),"") -> HIGH scoring chance. Finishing above its xG — regression risk. Faces Jets (opp avg D-Score 21).
A7: 2 | B7: =IFERROR(INDEX('Line Stats'!$A$6:$A$69,MATCH(LARGE('Line Stats'!$X$6:$X$69,2),'Line Stats'!$X$6:$X$69,0)),"") -> Avalanche | C7: =IFERROR(INDEX('Line Stats'!$C$6:$C$69,MATCH(LARGE('Line Stats'!$X$6:$X$69,2),'Line Stats'!$X$6:$X$69,0)),"") -> FL3 | D7: =IFERROR(INDEX('Line Stats'!$B$6:$B$69,MATCH(LARGE('Line Stats'!$X$6:$X$69,2),'Line Stats'!$X$6:$X$69,0)),"") -> Jets | E7: =IFERROR(INDEX('Line Stats'!$S$6:$S$69,MATCH(LARGE('Line Stats'!$X$6:$X$69,2),'Line Stats'!$X$6:$X$69,0)),"") -> 71.8 | F7: =IFERROR(INDEX('Line Stats'!$T$6:$T$69,MATCH(LARGE('Line Stats'!$X$6:$X$69,2),'Line Stats'!$X$6:$X$69,0)),"") -> HIGH | G7: =IFERROR(INDEX('Line Stats'!$V$6:$V$69,MATCH(LARGE('Line Stats'!$X$6:$X$69,2),'Line Stats'!$X$6:$X$69,0)),"") -> HIGH scoring chance. Goals in line with chances. Faces Jets (opp avg D-Score 21).
A8: 3 | B8: =IFERROR(INDEX('Line Stats'!$A$6:$A$69,MATCH(LARGE('Line Stats'!$X$6:$X$69,3),'Line Stats'!$X$6:$X$69,0)),"") -> Penguins | C8: =IFERROR(INDEX('Line Stats'!$C$6:$C$69,MATCH(LARGE('Line Stats'!$X$6:$X$69,3),'Line Stats'!$X$6:$X$69,0)),"") -> FL2 | D8: =IFERROR(INDEX('Line Stats'!$B$6:$B$69,MATCH(LARGE('Line Stats'!$X$6:$X$69,3),'Line Stats'!$X$6:$X$69,0)),"") -> Capitals | E8: =IFERROR(INDEX('Line Stats'!$S$6:$S$69,MATCH(LARGE('Line Stats'!$X$6:$X$69,3),'Line Stats'!$X$6:$X$69,0)),"") -> 71.8 | F8: =IFERROR(INDEX('Line Stats'!$T$6:$T$69,MATCH(LARGE('Line Stats'!$X$6:$X$69,3),'Line Stats'!$X$6:$X$69,0)),"") -> HIGH | G8: =IFERROR(INDEX('Line Stats'!$V$6:$V$69,MATCH(LARGE('Line Stats'!$X$6:$X$69,3),'Line Stats'!$X$6:$X$69,0)),"") -> HIGH scoring chance. Goals in line with chances. Top-3 high-danger creator on the slate. Faces Capitals (opp avg D-Score 52).
A11: TEAM-BY-TEAM
A12: # | B12: Team | C12: Opponent | D12: Team Scoring Chance | E12: Avg O-Score | F12: Opp Avg D-Score | G12: Best Line | H12: Best Line Index | I12: Outlook
A13: 1 | B13: =IFERROR(INDEX('Line Stats'!$A$6:$A$69,MATCH(A13,'Line Stats'!$W$6:$W$69,0)),"") -> Capitals | C13: =IF(B13="","",INDEX('Line Stats'!$B$6:$B$69,MATCH(B13,'Line Stats'!$A$6:$A$69,0))) -> Penguins | D13: =IF(B13="","",IFERROR(ROUND(SUMIF('Line Stats'!$A$6:$A$69,B13,'Line Stats'!$Y$6:$Y$69)/SUMIF('Line Stats'!$A$6:$A$69,B13,'Line Stats'!$Z$6:$Z$69),1),"")) -> 43.8 | E13: =IF(B13="","",ROUND(AVERAGEIF('Line Stats'!$A$6:$A$69,B13,'Line Stats'!$J$6:$J$69),1)) -> 40.6 | F13: =IF(B13="","",IFERROR(ROUND(AVERAGEIF('Line Stats'!$A$6:$A$69,C13,'Line Stats'!$P$6:$P$69),1),"")) -> 44.8 | G13: =IF(B13="","",IFERROR(INDEX('Line Stats'!$C$6:$C$69,MATCH(_xlfn.MAXIFS('Line Stats'!$X$6:$X$69,'Line Stats'!$A$6:$A$69,B13),'Line Stats'!$X$6:$X$69,0)),"")) -> FL2 | H13: =IF(B13="","",IFERROR(INDEX('Line Stats'!$S$6:$S$69,MATCH(_xlfn.MAXIFS('Line Stats'!$X$6:$X$69,'Line Stats'!$A$6:$A$69,B13),'Line Stats'!$X$6:$X$69,0)),"")) -> 66.3 | I13: =IF(B13="","",IF(D13="","No usable data",IF(D13>=Settings!$B$11,"HIGH — strong scoring spot. Lean team total over / stack "&G13&".",IF(D13>=Settings!$B$12,"MEDIUM — playable; focus on "&G13&".","LOW — tough scoring night.")))) -> LOW — tough scoring night.
A14: 2 | B14: =IFERROR(INDEX('Line Stats'!$A$6:$A$69,MATCH(A14,'Line Stats'!$W$6:$W$69,0)),"") -> Penguins | C14: =IF(B14="","",INDEX('Line Stats'!$B$6:$B$69,MATCH(B14,'Line Stats'!$A$6:$A$69,0))) -> Capitals | D14: =IF(B14="","",IFERROR(ROUND(SUMIF('Line Stats'!$A$6:$A$69,B14,'Line Stats'!$Y$6:$Y$69)/SUMIF('Line Stats'!$A$6:$A$69,B14,'Line Stats'!$Z$6:$Z$69),1),"")) -> 62 | E14: =IF(B14="","",ROUND(AVERAGEIF('Line Stats'!$A$6:$A$69,B14,'Line Stats'!$J$6:$J$69),1)) -> 60.4 | F14: =IF(B14="","",IFERROR(ROUND(AVERAGEIF('Line Stats'!$A$6:$A$69,C14,'Line Stats'!$P$6:$P$69),1),"")) -> 52.1 | G14: =IF(B14="","",IFERROR(INDEX('Line Stats'!$C$6:$C$69,MATCH(_xlfn.MAXIFS('Line Stats'!$X$6:$X$69,'Line Stats'!$A$6:$A$69,B14),'Line Stats'!$X$6:$X$69,0)),"")) -> FL2 | H14: =IF(B14="","",IFERROR(INDEX('Line Stats'!$S$6:$S$69,MATCH(_xlfn.MAXIFS('Line Stats'!$X$6:$X$69,'Line Stats'!$A$6:$A$69,B14),'Line Stats'!$X$6:$X$69,0)),"")) -> 71.8 | I14: =IF(B14="","",IF(D14="","No usable data",IF(D14>=Settings!$B$11,"HIGH — strong scoring spot. Lean team total over / stack "&G14&".",IF(D14>=Settings!$B$12,"MEDIUM — playable; focus on "&G14&".","LOW — tough scoring night.")))) -> HIGH — strong scoring spot. Lean team total over / stack FL2.
A15: 3 | B15: =IFERROR(INDEX('Line Stats'!$A$6:$A$69,MATCH(A15,'Line Stats'!$W$6:$W$69,0)),"") -> Ducks | C15: =IF(B15="","",INDEX('Line Stats'!$B$6:$B$69,MATCH(B15,'Line Stats'!$A$6:$A$69,0))) -> Oilers | D15: =IF(B15="","",IFERROR(ROUND(SUMIF('Line Stats'!$A$6:$A$69,B15,'Line Stats'!$Y$6:$Y$69)/SUMIF('Line Stats'!$A$6:$A$69,B15,'Line Stats'!$Z$6:$Z$69),1),"")) -> 35.5 | E15: =IF(B15="","",ROUND(AVERAGEIF('Line Stats'!$A$6:$A$69,B15,'Line Stats'!$J$6:$J$69),1)) -> 39.6 | F15: =IF(B15="","",IFERROR(ROUND(AVERAGEIF('Line Stats'!$A$6:$A$69,C15,'Line Stats'!$P$6:$P$69),1),"")) -> 75 | G15: =IF(B15="","",IFERROR(INDEX('Line Stats'!$C$6:$C$69,MATCH(_xlfn.MAXIFS('Line Stats'!$X$6:$X$69,'Line Stats'!$A$6:$A$69,B15),'Line Stats'!$X$6:$X$69,0)),"")) -> FL2 | H15: =IF(B15="","",IFERROR(INDEX('Line Stats'!$S$6:$S$69,MATCH(_xlfn.MAXIFS('Line Stats'!$X$6:$X$69,'Line Stats'!$A$6:$A$69,B15),'Line Stats'!$X$6:$X$69,0)),"")) -> 48 | I15: =IF(B15="","",IF(D15="","No usable data",IF(D15>=Settings!$B$11,"HIGH — strong scoring spot. Lean team total over / stack "&G15&".",IF(D15>=Settings!$B$12,"MEDIUM — playable; focus on "&G15&".","LOW — tough scoring night.")))) -> LOW — tough scoring night.
A16: 4 | B16: =IFERROR(INDEX('Line Stats'!$A$6:$A$69,MATCH(A16,'Line Stats'!$W$6:$W$69,0)),"") -> Oilers | C16: =IF(B16="","",INDEX('Line Stats'!$B$6:$B$69,MATCH(B16,'Line Stats'!$A$6:$A$69,0))) -> Ducks | D16: =IF(B16="","",IFERROR(ROUND(SUMIF('Line Stats'!$A$6:$A$69,B16,'Line Stats'!$Y$6:$Y$69)/SUMIF('Line Stats'!$A$6:$A$69,B16,'Line Stats'!$Z$6:$Z$69),1),"")) -> 48.5 | E16: =IF(B16="","",ROUND(AVERAGEIF('Line Stats'!$A$6:$A$69,B16,'Line Stats'!$J$6:$J$69),1)) -> 60.4 | F16: =IF(B16="","",IFERROR(ROUND(AVERAGEIF('Line Stats'!$A$6:$A$69,C16,'Line Stats'!$P$6:$P$69),1),"")) -> 60.4 | G16: =IF(B16="","",IFERROR(INDEX('Line Stats'!$C$6:$C$69,MATCH(_xlfn.MAXIFS('Line Stats'!$X$6:$X$69,'Line Stats'!$A$6:$A$69,B16),'Line Stats'!$X$6:$X$69,0)),"")) -> FL1 | H16: =IF(B16="","",IFERROR(INDEX('Line Stats'!$S$6:$S$69,MATCH(_xlfn.MAXIFS('Line Stats'!$X$6:$X$69,'Line Stats'!$A$6:$A$69,B16),'Line Stats'!$X$6:$X$69,0)),"")) -> 57.5 | I16: =IF(B16="","",IF(D16="","No usable data",IF(D16>=Settings!$B$11,"HIGH — strong scoring spot. Lean team total over / stack "&G16&".",IF(D16>=Settings!$B$12,"MEDIUM — playable; focus on "&G16&".","LOW — tough scoring night.")))) -> MEDIUM — playable; focus on FL1.
A17: 5 | B17: =IFERROR(INDEX('Line Stats'!$A$6:$A$69,MATCH(A17,'Line Stats'!$W$6:$W$69,0)),"") -> Jets | C17: =IF(B17="","",INDEX('Line Stats'!$B$6:$B$69,MATCH(B17,'Line Stats'!$A$6:$A$69,0))) -> Avalanche | D17: =IF(B17="","",IFERROR(ROUND(SUMIF('Line Stats'!$A$6:$A$69,B17,'Line Stats'!$Y$6:$Y$69)/SUMIF('Line Stats'!$A$6:$A$69,B17,'Line Stats'!$Z$6:$Z$69),1),"")) -> 56.6 | E17: =IF(B17="","",ROUND(AVERAGEIF('Line Stats'!$A$6:$A$69,B17,'Line Stats'!$J$6:$J$69),1)) -> 39.6 | F17: =IF(B17="","",IFERROR(ROUND(AVERAGEIF('Line Stats'!$A$6:$A$69,C17,'Line Stats'!$P$6:$P$69),1),"")) -> 59.4 | G17: =IF(B17="","",IFERROR(INDEX('Line Stats'!$C$6:$C$69,MATCH(_xlfn.MAXIFS('Line Stats'!$X$6:$X$69,'Line Stats'!$A$6:$A$69,B17),'Line Stats'!$X$6:$X$69,0)),"")) -> FL1 | H17: =IF(B17="","",IFERROR(INDEX('Line Stats'!$S$6:$S$69,MATCH(_xlfn.MAXIFS('Line Stats'!$X$6:$X$69,'Line Stats'!$A$6:$A$69,B17),'Line Stats'!$X$6:$X$69,0)),"")) -> 60.9 | I17: =IF(B17="","",IF(D17="","No usable data",IF(D17>=Settings!$B$11,"HIGH — strong scoring spot. Lean team total over / stack "&G17&".",IF(D17>=Settings!$B$12,"MEDIUM — playable; focus on "&G17&".","LOW — tough scoring night.")))) -> MEDIUM — playable; focus on FL1.
A18: 6 | B18: =IFERROR(INDEX('Line Stats'!$A$6:$A$69,MATCH(A18,'Line Stats'!$W$6:$W$69,0)),"") -> Avalanche | C18: =IF(B18="","",INDEX('Line Stats'!$B$6:$B$69,MATCH(B18,'Line Stats'!$A$6:$A$69,0))) -> Jets | D18: =IF(B18="","",IFERROR(ROUND(SUMIF('Line Stats'!$A$6:$A$69,B18,'Line Stats'!$Y$6:$Y$69)/SUMIF('Line Stats'!$A$6:$A$69,B18,'Line Stats'!$Z$6:$Z$69),1),"")) -> 78.1 | E18: =IF(B18="","",ROUND(AVERAGEIF('Line Stats'!$A$6:$A$69,B18,'Line Stats'!$J$6:$J$69),1)) -> 71.9 | F18: =IF(B18="","",IFERROR(ROUND(AVERAGEIF('Line Stats'!$A$6:$A$69,C18,'Line Stats'!$P$6:$P$69),1),"")) -> 20.8 | G18: =IF(B18="","",IFERROR(INDEX('Line Stats'!$C$6:$C$69,MATCH(_xlfn.MAXIFS('Line Stats'!$X$6:$X$69,'Line Stats'!$A$6:$A$69,B18),'Line Stats'!$X$6:$X$69,0)),"")) -> FL1 | H18: =IF(B18="","",IFERROR(INDEX('Line Stats'!$S$6:$S$69,MATCH(_xlfn.MAXIFS('Line Stats'!$X$6:$X$69,'Line Stats'!$A$6:$A$69,B18),'Line Stats'!$X$6:$X$69,0)),"")) -> 87.8 | I18: =IF(B18="","",IF(D18="","No usable data",IF(D18>=Settings!$B$11,"HIGH — strong scoring spot. Lean team total over / stack "&G18&".",IF(D18>=Settings!$B$12,"MEDIUM — playable; focus on "&G18&".","LOW — tough scoring night.")))) -> HIGH — strong scoring spot. Lean team total over / stack FL1.
A19: 7 | B19: =IFERROR(INDEX('Line Stats'!$A$6:$A$69,MATCH(A19,'Line Stats'!$W$6:$W$69,0)),"") | C19: =IF(B19="","",INDEX('Line Stats'!$B$6:$B$69,MATCH(B19,'Line Stats'!$A$6:$A$69,0))) | D19: =IF(B19="","",IFERROR(ROUND(SUMIF('Line Stats'!$A$6:$A$69,B19,'Line Stats'!$Y$6:$Y$69)/SUMIF('Line Stats'!$A$6:$A$69,B19,'Line Stats'!$Z$6:$Z$69),1),"")) | E19: =IF(B19="","",ROUND(AVERAGEIF('Line Stats'!$A$6:$A$69,B19,'Line Stats'!$J$6:$J$69),1)) | F19: =IF(B19="","",IFERROR(ROUND(AVERAGEIF('Line Stats'!$A$6:$A$69,C19,'Line Stats'!$P$6:$P$69),1),"")) | G19: =IF(B19="","",IFERROR(INDEX('Line Stats'!$C$6:$C$69,MATCH(_xlfn.MAXIFS('Line Stats'!$X$6:$X$69,'Line Stats'!$A$6:$A$69,B19),'Line Stats'!$X$6:$X$69,0)),"")) | H19: =IF(B19="","",IFERROR(INDEX('Line Stats'!$S$6:$S$69,MATCH(_xlfn.MAXIFS('Line Stats'!$X$6:$X$69,'Line Stats'!$A$6:$A$69,B19),'Line Stats'!$X$6:$X$69,0)),"")) | I19: =IF(B19="","",IF(D19="","No usable data",IF(D19>=Settings!$B$11,"HIGH — strong scoring spot. Lean team total over / stack "&G19&".",IF(D19>=Settings!$B$12,"MEDIUM — playable; focus on "&G19&".","LOW — tough scoring night."))))
A20: 8 | B20: =IFERROR(INDEX('Line Stats'!$A$6:$A$69,MATCH(A20,'Line Stats'!$W$6:$W$69,0)),"") | C20: =IF(B20="","",INDEX('Line Stats'!$B$6:$B$69,MATCH(B20,'Line Stats'!$A$6:$A$69,0))) | D20: =IF(B20="","",IFERROR(ROUND(SUMIF('Line Stats'!$A$6:$A$69,B20,'Line Stats'!$Y$6:$Y$69)/SUMIF('Line Stats'!$A$6:$A$69,B20,'Line Stats'!$Z$6:$Z$69),1),"")) | E20: =IF(B20="","",ROUND(AVERAGEIF('Line Stats'!$A$6:$A$69,B20,'Line Stats'!$J$6:$J$69),1)) | F20: =IF(B20="","",IFERROR(ROUND(AVERAGEIF('Line Stats'!$A$6:$A$69,C20,'Line Stats'!$P$6:$P$69),1),"")) | G20: =IF(B20="","",IFERROR(INDEX('Line Stats'!$C$6:$C$69,MATCH(_xlfn.MAXIFS('Line Stats'!$X$6:$X$69,'Line Stats'!$A$6:$A$69,B20),'Line Stats'!$X$6:$X$69,0)),"")) | H20: =IF(B20="","",IFERROR(INDEX('Line Stats'!$S$6:$S$69,MATCH(_xlfn.MAXIFS('Line Stats'!$X$6:$X$69,'Line Stats'!$A$6:$A$69,B20),'Line Stats'!$X$6:$X$69,0)),"")) | I20: =IF(B20="","",IF(D20="","No usable data",IF(D20>=Settings!$B$11,"HIGH — strong scoring spot. Lean team total over / stack "&G20&".",IF(D20>=Settings!$B$12,"MEDIUM — playable; focus on "&G20&".","LOW — tough scoring night."))))
A21: 9 | B21: =IFERROR(INDEX('Line Stats'!$A$6:$A$69,MATCH(A21,'Line Stats'!$W$6:$W$69,0)),"") | C21: =IF(B21="","",INDEX('Line Stats'!$B$6:$B$69,MATCH(B21,'Line Stats'!$A$6:$A$69,0))) | D21: =IF(B21="","",IFERROR(ROUND(SUMIF('Line Stats'!$A$6:$A$69,B21,'Line Stats'!$Y$6:$Y$69)/SUMIF('Line Stats'!$A$6:$A$69,B21,'Line Stats'!$Z$6:$Z$69),1),"")) | E21: =IF(B21="","",ROUND(AVERAGEIF('Line Stats'!$A$6:$A$69,B21,'Line Stats'!$J$6:$J$69),1)) | F21: =IF(B21="","",IFERROR(ROUND(AVERAGEIF('Line Stats'!$A$6:$A$69,C21,'Line Stats'!$P$6:$P$69),1),"")) | G21: =IF(B21="","",IFERROR(INDEX('Line Stats'!$C$6:$C$69,MATCH(_xlfn.MAXIFS('Line Stats'!$X$6:$X$69,'Line Stats'!$A$6:$A$69,B21),'Line Stats'!$X$6:$X$69,0)),"")) | H21: =IF(B21="","",IFERROR(INDEX('Line Stats'!$S$6:$S$69,MATCH(_xlfn.MAXIFS('Line Stats'!$X$6:$X$69,'Line Stats'!$A$6:$A$69,B21),'Line Stats'!$X$6:$X$69,0)),"")) | I21: =IF(B21="","",IF(D21="","No usable data",IF(D21>=Settings!$B$11,"HIGH — strong scoring spot. Lean team total over / stack "&G21&".",IF(D21>=Settings!$B$12,"MEDIUM — playable; focus on "&G21&".","LOW — tough scoring night."))))
A22: 10 | B22: =IFERROR(INDEX('Line Stats'!$A$6:$A$69,MATCH(A22,'Line Stats'!$W$6:$W$69,0)),"") | C22: =IF(B22="","",INDEX('Line Stats'!$B$6:$B$69,MATCH(B22,'Line Stats'!$A$6:$A$69,0))) | D22: =IF(B22="","",IFERROR(ROUND(SUMIF('Line Stats'!$A$6:$A$69,B22,'Line Stats'!$Y$6:$Y$69)/SUMIF('Line Stats'!$A$6:$A$69,B22,'Line Stats'!$Z$6:$Z$69),1),"")) | E22: =IF(B22="","",ROUND(AVERAGEIF('Line Stats'!$A$6:$A$69,B22,'Line Stats'!$J$6:$J$69),1)) | F22: =IF(B22="","",IFERROR(ROUND(AVERAGEIF('Line Stats'!$A$6:$A$69,C22,'Line Stats'!$P$6:$P$69),1),"")) | G22: =IF(B22="","",IFERROR(INDEX('Line Stats'!$C$6:$C$69,MATCH(_xlfn.MAXIFS('Line Stats'!$X$6:$X$69,'Line Stats'!$A$6:$A$69,B22),'Line Stats'!$X$6:$X$69,0)),"")) | H22: =IF(B22="","",IFERROR(INDEX('Line Stats'!$S$6:$S$69,MATCH(_xlfn.MAXIFS('Line Stats'!$X$6:$X$69,'Line Stats'!$A$6:$A$69,B22),'Line Stats'!$X$6:$X$69,0)),"")) | I22: =IF(B22="","",IF(D22="","No usable data",IF(D22>=Settings!$B$11,"HIGH — strong scoring spot. Lean team total over / stack "&G22&".",IF(D22>=Settings!$B$12,"MEDIUM — playable; focus on "&G22&".","LOW — tough scoring night."))))
A23: 11 | B23: =IFERROR(INDEX('Line Stats'!$A$6:$A$69,MATCH(A23,'Line Stats'!$W$6:$W$69,0)),"") | C23: =IF(B23="","",INDEX('Line Stats'!$B$6:$B$69,MATCH(B23,'Line Stats'!$A$6:$A$69,0))) | D23: =IF(B23="","",IFERROR(ROUND(SUMIF('Line Stats'!$A$6:$A$69,B23,'Line Stats'!$Y$6:$Y$69)/SUMIF('Line Stats'!$A$6:$A$69,B23,'Line Stats'!$Z$6:$Z$69),1),"")) | E23: =IF(B23="","",ROUND(AVERAGEIF('Line Stats'!$A$6:$A$69,B23,'Line Stats'!$J$6:$J$69),1)) | F23: =IF(B23="","",IFERROR(ROUND(AVERAGEIF('Line Stats'!$A$6:$A$69,C23,'Line Stats'!$P$6:$P$69),1),"")) | G23: =IF(B23="","",IFERROR(INDEX('Line Stats'!$C$6:$C$69,MATCH(_xlfn.MAXIFS('Line Stats'!$X$6:$X$69,'Line Stats'!$A$6:$A$69,B23),'Line Stats'!$X$6:$X$69,0)),"")) | H23: =IF(B23="","",IFERROR(INDEX('Line Stats'!$S$6:$S$69,MATCH(_xlfn.MAXIFS('Line Stats'!$X$6:$X$69,'Line Stats'!$A$6:$A$69,B23),'Line Stats'!$X$6:$X$69,0)),"")) | I23: =IF(B23="","",IF(D23="","No usable data",IF(D23>=Settings!$B$11,"HIGH — strong scoring spot. Lean team total over / stack "&G23&".",IF(D23>=Settings!$B$12,"MEDIUM — playable; focus on "&G23&".","LOW — tough scoring night."))))
A24: 12 | B24: =IFERROR(INDEX('Line Stats'!$A$6:$A$69,MATCH(A24,'Line Stats'!$W$6:$W$69,0)),"") | C24: =IF(B24="","",INDEX('Line Stats'!$B$6:$B$69,MATCH(B24,'Line Stats'!$A$6:$A$69,0))) | D24: =IF(B24="","",IFERROR(ROUND(SUMIF('Line Stats'!$A$6:$A$69,B24,'Line Stats'!$Y$6:$Y$69)/SUMIF('Line Stats'!$A$6:$A$69,B24,'Line Stats'!$Z$6:$Z$69),1),"")) | E24: =IF(B24="","",ROUND(AVERAGEIF('Line Stats'!$A$6:$A$69,B24,'Line Stats'!$J$6:$J$69),1)) | F24: =IF(B24="","",IFERROR(ROUND(AVERAGEIF('Line Stats'!$A$6:$A$69,C24,'Line Stats'!$P$6:$P$69),1),"")) | G24: =IF(B24="","",IFERROR(INDEX('Line Stats'!$C$6:$C$69,MATCH(_xlfn.MAXIFS('Line Stats'!$X$6:$X$69,'Line Stats'!$A$6:$A$69,B24),'Line Stats'!$X$6:$X$69,0)),"")) | H24: =IF(B24="","",IFERROR(INDEX('Line Stats'!$S$6:$S$69,MATCH(_xlfn.MAXIFS('Line Stats'!$X$6:$X$69,'Line Stats'!$A$6:$A$69,B24),'Line Stats'!$X$6:$X$69,0)),"")) | I24: =IF(B24="","",IF(D24="","No usable data",IF(D24>=Settings!$B$11,"HIGH — strong scoring spot. Lean team total over / stack "&G24&".",IF(D24>=Settings!$B$12,"MEDIUM — playable; focus on "&G24&".","LOW — tough scoring night."))))
... A44: 32 | B44: =IFERROR(INDEX('Line Stats'!$A$6:$A$69,MATCH(A44,'Line Stats'!$W$6:$W$69,0)),"") | C44: =IF(B44="","",INDEX('Line Stats'!$B$6:$B$69,MATCH(B44,'Line Stats'!$A$6:$A$69,0))) | D44: =IF(B44="","",IFERROR(ROUND(SUMIF('Line Stats'!$A$6:$A$69,B44,'Line Stats'!$Y$6:$Y$69)/SUMIF('Line Stats'!$A$6:$A$69,B44,'Line Stats'!$Z$6:$Z$69),1),"")) | E44: =IF(B44="","",ROUND(AVERAGEIF('Line Stats'!$A$6:$A$69,B44,'Line Stats'!$J$6:$J$69),1)) | F44: =IF(B44="","",IFERROR(ROUND(AVERAGEIF('Line Stats'!$A$6:$A$69,C44,'Line Stats'!$P$6:$P$69),1),"")) | G44: =IF(B44="","",IFERROR(INDEX('Line Stats'!$C$6:$C$69,MATCH(_xlfn.MAXIFS('Line Stats'!$X$6:$X$69,'Line Stats'!$A$6:$A$69,B44),'Line Stats'!$X$6:$X$69,0)),"")) | H44: =IF(B44="","",IFERROR(INDEX('Line Stats'!$S$6:$S$69,MATCH(_xlfn.MAXIFS('Line Stats'!$X$6:$X$69,'Line Stats'!$A$6:$A$69,B44),'Line Stats'!$X$6:$X$69,0)),"")) | I44: =IF(B44="","",IF(D44="","No usable data",IF(D44>=Settings!$B$11,"HIGH — strong scoring spot. Lean team total over / stack "&G44&".",IF(D44>=Settings!$B$12,"MEDIUM — playable; focus on "&G44&".","LOW — tough scoring night."))))

Sheet Goalies
A1: WCS ANALYTICS — STARTING GOALIES & WEAKNESS BY SHOOTER POSITION
A2: Starters: Daily Faceoff. Shot splits: MoneyPuck.com shot data (2025-26 + 2026-27 regular season). Blue columns are filled by wcs_goalie_update.py (or by hand). GSAx/100 = goals saved above expected per 100 unblocked shots — POSITIVE = better than expected (green), NEGATIVE = weakness (red).
A3: Slate date: | B3: 2026-10-07
A4: STARTER | G4: vs LEFT WING | I4: vs RIGHT WING | K4: vs CENTER | M4: vs DEFENSE | O4: OVERALL | Q4: WCS SCOUTING (auto)
A5: Team | B5: Goalie | C5: Status | D5: Opponent | E5: Total SOG | F5: Fewest SOG (any pos) | G5: Sv% | H5: GSAx/100 | I5: Sv% | J5: GSAx/100 | K5: Sv% | L5: GSAx/100 | M5: Sv% | N5: GSAx/100 | O5: Sv% | P5: GSAx/100 | Q5: Weakest vs | R5: Strongest vs | S5: Scouting Note
A6: Avalanche | B6: Mackenzie Blackwood | C6: Likely | D6: Jets | Q6: =IF(COUNT(H6,J6,L6,N6)<4,"",IF(MIN(H6,J6,L6,N6)=H6,"LW",IF(MIN(H6,J6,L6,N6)=J6,"RW",IF(MIN(H6,J6,L6,N6)=L6,"C","D")))) | R6: =IF(COUNT(H6,J6,L6,N6)<4,"",IF(MAX(H6,J6,L6,N6)=H6,"LW",IF(MAX(H6,J6,L6,N6)=J6,"RW",IF(MAX(H6,J6,L6,N6)=L6,"C","D")))) | S6: =IF(B6="","",IF(Q6="","Splits not loaded yet — run wcs_goalie_update.py (or no NHL history for this goalie).",IF(F6<Settings!$B$20,"SMALL SAMPLE — ","")&"Weakest vs "&IF(Q6="LW","left wingers",IF(Q6="RW","right wingers",IF(Q6="C","centers","defensemen (point shots)")))&" ("&TEXT(MIN(H6,J6,L6,N6),"+0.00;-0.00")&" GSAx/100). "&IF(MIN(H6,J6,L6,N6)<0,"Target: "&D6&" "&IF(Q6="D","D-men shooting from the point","players at "&Q6)&IF(IFERROR(INDEX('Team Outlook'!$G$13:$G$44,MATCH(D6,'Team Outlook'!$B$13:$B$44,0)),"")="",""," — best "&D6&" line tonight: "&IFERROR(INDEX('Team Outlook'!$G$13:$G$44,MATCH(D6,'Team Outlook'!$B$13:$B$44,0)),""))&".","No real hole — above expected at every position."))) -> Splits not loaded yet — run wcs_goalie_update.py (or no NHL history for this goalie).
A7: Jets | B7: Stuart Skinner | C7: Unconfirmed | D7: Avalanche | Q7: =IF(COUNT(H7,J7,L7,N7)<4,"",IF(MIN(H7,J7,L7,N7)=H7,"LW",IF(MIN(H7,J7,L7,N7)=J7,"RW",IF(MIN(H7,J7,L7,N7)=L7,"C","D")))) | R7: =IF(COUNT(H7,J7,L7,N7)<4,"",IF(MAX(H7,J7,L7,N7)=H7,"LW",IF(MAX(H7,J7,L7,N7)=J7,"RW",IF(MAX(H7,J7,L7,N7)=L7,"C","D")))) | S7: =IF(B7="","",IF(Q7="","Splits not loaded yet — run wcs_goalie_update.py (or no NHL history for this goalie).",IF(F7<Settings!$B$20,"SMALL SAMPLE — ","")&"Weakest vs "&IF(Q7="LW","left wingers",IF(Q7="RW","right wingers",IF(Q7="C","centers","defensemen (point shots)")))&" ("&TEXT(MIN(H7,J7,L7,N7),"+0.00;-0.00")&" GSAx/100). "&IF(MIN(H7,J7,L7,N7)<0,"Target: "&D7&" "&IF(Q7="D","D-men shooting from the point","players at "&Q7)&IF(IFERROR(INDEX('Team Outlook'!$G$13:$G$44,MATCH(D7,'Team Outlook'!$B$13:$B$44,0)),"")="",""," — best "&D7&" line tonight: "&IFERROR(INDEX('Team Outlook'!$G$13:$G$44,MATCH(D7,'Team Outlook'!$B$13:$B$44,0)),""))&".","No real hole — above expected at every position."))) -> Splits not loaded yet — run wcs_goalie_update.py (or no NHL history for this goalie).
A8: Penguins | B8: Arturs Silovs | C8: Confirmed | D8: Capitals | Q8: =IF(COUNT(H8,J8,L8,N8)<4,"",IF(MIN(H8,J8,L8,N8)=H8,"LW",IF(MIN(H8,J8,L8,N8)=J8,"RW",IF(MIN(H8,J8,L8,N8)=L8,"C","D")))) | R8: =IF(COUNT(H8,J8,L8,N8)<4,"",IF(MAX(H8,J8,L8,N8)=H8,"LW",IF(MAX(H8,J8,L8,N8)=J8,"RW",IF(MAX(H8,J8,L8,N8)=L8,"C","D")))) | S8: =IF(B8="","",IF(Q8="","Splits not loaded yet — run wcs_goalie_update.py (or no NHL history for this goalie).",IF(F8<Settings!$B$20,"SMALL SAMPLE — ","")&"Weakest vs "&IF(Q8="LW","left wingers",IF(Q8="RW","right wingers",IF(Q8="C","centers","defensemen (point shots)")))&" ("&TEXT(MIN(H8,J8,L8,N8),"+0.00;-0.00")&" GSAx/100). "&IF(MIN(H8,J8,L8,N8)<0,"Target: "&D8&" "&IF(Q8="D","D-men shooting from the point","players at "&Q8)&IF(IFERROR(INDEX('Team Outlook'!$G$13:$G$44,MATCH(D8,'Team Outlook'!$B$13:$B$44,0)),"")="",""," — best "&D8&" line tonight: "&IFERROR(INDEX('Team Outlook'!$G$13:$G$44,MATCH(D8,'Team Outlook'!$B$13:$B$44,0)),""))&".","No real hole — above expected at every position."))) -> Splits not loaded yet — run wcs_goalie_update.py (or no NHL history for this goalie).
A9: Capitals | B9: Logan Thompson | C9: Confirmed | D9: Penguins | Q9: =IF(COUNT(H9,J9,L9,N9)<4,"",IF(MIN(H9,J9,L9,N9)=H9,"LW",IF(MIN(H9,J9,L9,N9)=J9,"RW",IF(MIN(H9,J9,L9,N9)=L9,"C","D")))) | R9: =IF(COUNT(H9,J9,L9,N9)<4,"",IF(MAX(H9,J9,L9,N9)=H9,"LW",IF(MAX(H9,J9,L9,N9)=J9,"RW",IF(MAX(H9,J9,L9,N9)=L9,"C","D")))) | S9: =IF(B9="","",IF(Q9="","Splits not loaded yet — run wcs_goalie_update.py (or no NHL history for this goalie).",IF(F9<Settings!$B$20,"SMALL SAMPLE — ","")&"Weakest vs "&IF(Q9="LW","left wingers",IF(Q9="RW","right wingers",IF(Q9="C","centers","defensemen (point shots)")))&" ("&TEXT(MIN(H9,J9,L9,N9),"+0.00;-0.00")&" GSAx/100). "&IF(MIN(H9,J9,L9,N9)<0,"Target: "&D9&" "&IF(Q9="D","D-men shooting from the point","players at "&Q9)&IF(IFERROR(INDEX('Team Outlook'!$G$13:$G$44,MATCH(D9,'Team Outlook'!$B$13:$B$44,0)),"")="",""," — best "&D9&" line tonight: "&IFERROR(INDEX('Team Outlook'!$G$13:$G$44,MATCH(D9,'Team Outlook'!$B$13:$B$44,0)),""))&".","No real hole — above expected at every position."))) -> Splits not loaded yet — run wcs_goalie_update.py (or no NHL history for this goalie).
A10: Oilers | B10: Devon Levi | C10: Confirmed | D10: Ducks | Q10: =IF(COUNT(H10,J10,L10,N10)<4,"",IF(MIN(H10,J10,L10,N10)=H10,"LW",IF(MIN(H10,J10,L10,N10)=J10,"RW",IF(MIN(H10,J10,L10,N10)=L10,"C","D")))) | R10: =IF(COUNT(H10,J10,L10,N10)<4,"",IF(MAX(H10,J10,L10,N10)=H10,"LW",IF(MAX(H10,J10,L10,N10)=J10,"RW",IF(MAX(H10,J10,L10,N10)=L10,"C","D")))) | S10: =IF(B10="","",IF(Q10="","Splits not loaded yet — run wcs_goalie_update.py (or no NHL history for this goalie).",IF(F10<Settings!$B$20,"SMALL SAMPLE — ","")&"Weakest vs "&IF(Q10="LW","left wingers",IF(Q10="RW","right wingers",IF(Q10="C","centers","defensemen (point shots)")))&" ("&TEXT(MIN(H10,J10,L10,N10),"+0.00;-0.00")&" GSAx/100). "&IF(MIN(H10,J10,L10,N10)<0,"Target: "&D10&" "&IF(Q10="D","D-men shooting from the point","players at "&Q10)&IF(IFERROR(INDEX('Team Outlook'!$G$13:$G$44,MATCH(D10,'Team Outlook'!$B$13:$B$44,0)),"")="",""," — best "&D10&" line tonight: "&IFERROR(INDEX('Team Outlook'!$G$13:$G$44,MATCH(D10,'Team Outlook'!$B$13:$B$44,0)),""))&".","No real hole — above expected at every position."))) -> Splits not loaded yet — run wcs_goalie_update.py (or no NHL history for this goalie).
A11: Ducks | B11: Lukas Dostal | C11: Confirmed | D11: Oilers | Q11: =IF(COUNT(H11,J11,L11,N11)<4,"",IF(MIN(H11,J11,L11,N11)=H11,"LW",IF(MIN(H11,J11,L11,N11)=J11,"RW",IF(MIN(H11,J11,L11,N11)=L11,"C","D")))) | R11: =IF(COUNT(H11,J11,L11,N11)<4,"",IF(MAX(H11,J11,L11,N11)=H11,"LW",IF(MAX(H11,J11,L11,N11)=J11,"RW",IF(MAX(H11,J11,L11,N11)=L11,"C","D")))) | S11: =IF(B11="","",IF(Q11="","Splits not loaded yet — run wcs_goalie_update.py (or no NHL history for this goalie).",IF(F11<Settings!$B$20,"SMALL SAMPLE — ","")&"Weakest vs "&IF(Q11="LW","left wingers",IF(Q11="RW","right wingers",IF(Q11="C","centers","defensemen (point shots)")))&" ("&TEXT(MIN(H11,J11,L11,N11),"+0.00;-0.00")&" GSAx/100). "&IF(MIN(H11,J11,L11,N11)<0,"Target: "&D11&" "&IF(Q11="D","D-men shooting from the point","players at "&Q11)&IF(IFERROR(INDEX('Team Outlook'!$G$13:$G$44,MATCH(D11,'Team Outlook'!$B$13:$B$44,0)),"")="",""," — best "&D11&" line tonight: "&IFERROR(INDEX('Team Outlook'!$G$13:$G$44,MATCH(D11,'Team Outlook'!$B$13:$B$44,0)),""))&".","No real hole — above expected at every position."))) -> Splits not loaded yet — run wcs_goalie_update.py (or no NHL history for this goalie).
Q12: =IF(COUNT(H12,J12,L12,N12)<4,"",IF(MIN(H12,J12,L12,N12)=H12,"LW",IF(MIN(H12,J12,L12,N12)=J12,"RW",IF(MIN(H12,J12,L12,N12)=L12,"C","D")))) | R12: =IF(COUNT(H12,J12,L12,N12)<4,"",IF(MAX(H12,J12,L12,N12)=H12,"LW",IF(MAX(H12,J12,L12,N12)=J12,"RW",IF(MAX(H12,J12,L12,N12)=L12,"C","D")))) | S12: =IF(B12="","",IF(Q12="","Splits not loaded yet — run wcs_goalie_update.py (or no NHL history for this goalie).",IF(F12<Settings!$B$20,"SMALL SAMPLE — ","")&"Weakest vs "&IF(Q12="LW","left wingers",IF(Q12="RW","right wingers",IF(Q12="C","centers","defensemen (point shots)")))&" ("&TEXT(MIN(H12,J12,L12,N12),"+0.00;-0.00")&" GSAx/100). "&IF(MIN(H12,J12,L12,N12)<0,"Target: "&D12&" "&IF(Q12="D","D-men shooting from the point","players at "&Q12)&IF(IFERROR(INDEX('Team Outlook'!$G$13:$G$44,MATCH(D12,'Team Outlook'!$B$13:$B$44,0)),"")="",""," — best "&D12&" line tonight: "&IFERROR(INDEX('Team Outlook'!$G$13:$G$44,MATCH(D12,'Team Outlook'!$B$13:$B$44,0)),""))&".","No real hole — above expected at every position.")))
Q13: =IF(COUNT(H13,J13,L13,N13)<4,"",IF(MIN(H13,J13,L13,N13)=H13,"LW",IF(MIN(H13,J13,L13,N13)=J13,"RW",IF(MIN(H13,J13,L13,N13)=L13,"C","D")))) | R13: =IF(COUNT(H13,J13,L13,N13)<4,"",IF(MAX(H13,J13,L13,N13)=H13,"LW",IF(MAX(H13,J13,L13,N13)=J13,"RW",IF(MAX(H13,J13,L13,N13)=L13,"C","D")))) | S13: =IF(B13="","",IF(Q13="","Splits not loaded yet — run wcs_goalie_update.py (or no NHL history for this goalie).",IF(F13<Settings!$B$20,"SMALL SAMPLE — ","")&"Weakest vs "&IF(Q13="LW","left wingers",IF(Q13="RW","right wingers",IF(Q13="C","centers","defensemen (point shots)")))&" ("&TEXT(MIN(H13,J13,L13,N13),"+0.00;-0.00")&" GSAx/100). "&IF(MIN(H13,J13,L13,N13)<0,"Target: "&D13&" "&IF(Q13="D","D-men shooting from the point","players at "&Q13)&IF(IFERROR(INDEX('Team Outlook'!$G$13:$G$44,MATCH(D13,'Team Outlook'!$B$13:$B$44,0)),"")="",""," — best "&D13&" line tonight: "&IFERROR(INDEX('Team Outlook'!$G$13:$G$44,MATCH(D13,'Team Outlook'!$B$13:$B$44,0)),""))&".","No real hole — above expected at every position.")))
Q14: =IF(COUNT(H14,J14,L14,N14)<4,"",IF(MIN(H14,J14,L14,N14)=H14,"LW",IF(MIN(H14,J14,L14,N14)=J14,"RW",IF(MIN(H14,J14,L14,N14)=L14,"C","D")))) | R14: =IF(COUNT(H14,J14,L14,N14)<4,"",IF(MAX(H14,J14,L14,N14)=H14,"LW",IF(MAX(H14,J14,L14,N14)=J14,"RW",IF(MAX(H14,J14,L14,N14)=L14,"C","D")))) | S14: =IF(B14="","",IF(Q14="","Splits not loaded yet — run wcs_goalie_update.py (or no NHL history for this goalie).",IF(F14<Settings!$B$20,"SMALL SAMPLE — ","")&"Weakest vs "&IF(Q14="LW","left wingers",IF(Q14="RW","right wingers",IF(Q14="C","centers","defensemen (point shots)")))&" ("&TEXT(MIN(H14,J14,L14,N14),"+0.00;-0.00")&" GSAx/100). "&IF(MIN(H14,J14,L14,N14)<0,"Target: "&D14&" "&IF(Q14="D","D-men shooting from the point","players at "&Q14)&IF(IFERROR(INDEX('Team Outlook'!$G$13:$G$44,MATCH(D14,'Team Outlook'!$B$13:$B$44,0)),"")="",""," — best "&D14&" line tonight: "&IFERROR(INDEX('Team Outlook'!$G$13:$G$44,MATCH(D14,'Team Outlook'!$B$13:$B$44,0)),""))&".","No real hole — above expected at every position.")))
Q15: =IF(COUNT(H15,J15,L15,N15)<4,"",IF(MIN(H15,J15,L15,N15)=H15,"LW",IF(MIN(H15,J15,L15,N15)=J15,"RW",IF(MIN(H15,J15,L15,N15)=L15,"C","D")))) | R15: =IF(COUNT(H15,J15,L15,N15)<4,"",IF(MAX(H15,J15,L15,N15)=H15,"LW",IF(MAX(H15,J15,L15,N15)=J15,"RW",IF(MAX(H15,J15,L15,N15)=L15,"C","D")))) | S15: =IF(B15="","",IF(Q15="","Splits not loaded yet — run wcs_goalie_update.py (or no NHL history for this goalie).",IF(F15<Settings!$B$20,"SMALL SAMPLE — ","")&"Weakest vs "&IF(Q15="LW","left wingers",IF(Q15="RW","right wingers",IF(Q15="C","centers","defensemen (point shots)")))&" ("&TEXT(MIN(H15,J15,L15,N15),"+0.00;-0.00")&" GSAx/100). "&IF(MIN(H15,J15,L15,N15)<0,"Target: "&D15&" "&IF(Q15="D","D-men shooting from the point","players at "&Q15)&IF(IFERROR(INDEX('Team Outlook'!$G$13:$G$44,MATCH(D15,'Team Outlook'!$B$13:$B$44,0)),"")="",""," — best "&D15&" line tonight: "&IFERROR(INDEX('Team Outlook'!$G$13:$G$44,MATCH(D15,'Team Outlook'!$B$13:$B$44,0)),""))&".","No real hole — above expected at every position.")))
Q16: =IF(COUNT(H16,J16,L16,N16)<4,"",IF(MIN(H16,J16,L16,N16)=H16,"LW",IF(MIN(H16,J16,L16,N16)=J16,"RW",IF(MIN(H16,J16,L16,N16)=L16,"C","D")))) | R16: =IF(COUNT(H16,J16,L16,N16)<4,"",IF(MAX(H16,J16,L16,N16)=H16,"LW",IF(MAX(H16,J16,L16,N16)=J16,"RW",IF(MAX(H16,J16,L16,N16)=L16,"C","D")))) | S16: =IF(B16="","",IF(Q16="","Splits not loaded yet — run wcs_goalie_update.py (or no NHL history for this goalie).",IF(F16<Settings!$B$20,"SMALL SAMPLE — ","")&"Weakest vs "&IF(Q16="LW","left wingers",IF(Q16="RW","right wingers",IF(Q16="C","centers","defensemen (point shots)")))&" ("&TEXT(MIN(H16,J16,L16,N16),"+0.00;-0.00")&" GSAx/100). "&IF(MIN(H16,J16,L16,N16)<0,"Target: "&D16&" "&IF(Q16="D","D-men shooting from the point","players at "&Q16)&IF(IFERROR(INDEX('Team Outlook'!$G$13:$G$44,MATCH(D16,'Team Outlook'!$B$13:$B$44,0)),"")="",""," — best "&D16&" line tonight: "&IFERROR(INDEX('Team Outlook'!$G$13:$G$44,MATCH(D16,'Team Outlook'!$B$13:$B$44,0)),""))&".","No real hole — above expected at every position.")))
Q17: =IF(COUNT(H17,J17,L17,N17)<4,"",IF(MIN(H17,J17,L17,N17)=H17,"LW",IF(MIN(H17,J17,L17,N17)=J17,"RW",IF(MIN(H17,J17,L17,N17)=L17,"C","D")))) | R17: =IF(COUNT(H17,J17,L17,N17)<4,"",IF(MAX(H17,J17,L17,N17)=H17,"LW",IF(MAX(H17,J17,L17,N17)=J17,"RW",IF(MAX(H17,J17,L17,N17)=L17,"C","D")))) | S17: =IF(B17="","",IF(Q17="","Splits not loaded yet — run wcs_goalie_update.py (or no NHL history for this goalie).",IF(F17<Settings!$B$20,"SMALL SAMPLE — ","")&"Weakest vs "&IF(Q17="LW","left wingers",IF(Q17="RW","right wingers",IF(Q17="C","centers","defensemen (point shots)")))&" ("&TEXT(MIN(H17,J17,L17,N17),"+0.00;-0.00")&" GSAx/100). "&IF(MIN(H17,J17,L17,N17)<0,"Target: "&D17&" "&IF(Q17="D","D-men shooting from the point","players at "&Q17)&IF(IFERROR(INDEX('Team Outlook'!$G$13:$G$44,MATCH(D17,'Team Outlook'!$B$13:$B$44,0)),"")="",""," — best "&D17&" line tonight: "&IFERROR(INDEX('Team Outlook'!$G$13:$G$44,MATCH(D17,'Team Outlook'!$B$13:$B$44,0)),""))&".","No real hole — above expected at every position.")))
Q18: =IF(COUNT(H18,J18,L18,N18)<4,"",IF(MIN(H18,J18,L18,N18)=H18,"LW",IF(MIN(H18,J18,L18,N18)=J18,"RW",IF(MIN(H18,J18,L18,N18)=L18,"C","D")))) | R18: =IF(COUNT(H18,J18,L18,N18)<4,"",IF(MAX(H18,J18,L18,N18)=H18,"LW",IF(MAX(H18,J18,L18,N18)=J18,"RW",IF(MAX(H18,J18,L18,N18)=L18,"C","D")))) | S18: =IF(B18="","",IF(Q18="","Splits not loaded yet — run wcs_goalie_update.py (or no NHL history for this goalie).",IF(F18<Settings!$B$20,"SMALL SAMPLE — ","")&"Weakest vs "&IF(Q18="LW","left wingers",IF(Q18="RW","right wingers",IF(Q18="C","centers","defensemen (point shots)")))&" ("&TEXT(MIN(H18,J18,L18,N18),"+0.00;-0.00")&" GSAx/100). "&IF(MIN(H18,J18,L18,N18)<0,"Target: "&D18&" "&IF(Q18="D","D-men shooting from the point","players at "&Q18)&IF(IFERROR(INDEX('Team Outlook'!$G$13:$G$44,MATCH(D18,'Team Outlook'!$B$13:$B$44,0)),"")="",""," — best "&D18&" line tonight: "&IFERROR(INDEX('Team Outlook'!$G$13:$G$44,MATCH(D18,'Team Outlook'!$B$13:$B$44,0)),""))&".","No real hole — above expected at every position.")))
Q19: =IF(COUNT(H19,J19,L19,N19)<4,"",IF(MIN(H19,J19,L19,N19)=H19,"LW",IF(MIN(H19,J19,L19,N19)=J19,"RW",IF(MIN(H19,J19,L19,N19)=L19,"C","D")))) | R19: =IF(COUNT(H19,J19,L19,N19)<4,"",IF(MAX(H19,J19,L19,N19)=H19,"LW",IF(MAX(H19,J19,L19,N19)=J19,"RW",IF(MAX(H19,J19,L19,N19)=L19,"C","D")))) | S19: =IF(B19="","",IF(Q19="","Splits not loaded yet — run wcs_goalie_update.py (or no NHL history for this goalie).",IF(F19<Settings!$B$20,"SMALL SAMPLE — ","")&"Weakest vs "&IF(Q19="LW","left wingers",IF(Q19="RW","right wingers",IF(Q19="C","centers","defensemen (point shots)")))&" ("&TEXT(MIN(H19,J19,L19,N19),"+0.00;-0.00")&" GSAx/100). "&IF(MIN(H19,J19,L19,N19)<0,"Target: "&D19&" "&IF(Q19="D","D-men shooting from the point","players at "&Q19)&IF(IFERROR(INDEX('Team Outlook'!$G$13:$G$44,MATCH(D19,'Team Outlook'!$B$13:$B$44,0)),"")="",""," — best "&D19&" line tonight: "&IFERROR(INDEX('Team Outlook'!$G$13:$G$44,MATCH(D19,'Team Outlook'!$B$13:$B$44,0)),""))&".","No real hole — above expected at every position.")))
Q20: =IF(COUNT(H20,J20,L20,N20)<4,"",IF(MIN(H20,J20,L20,N20)=H20,"LW",IF(MIN(H20,J20,L20,N20)=J20,"RW",IF(MIN(H20,J20,L20,N20)=L20,"C","D")))) | R20: =IF(COUNT(H20,J20,L20,N20)<4,"",IF(MAX(H20,J20,L20,N20)=H20,"LW",IF(MAX(H20,J20,L20,N20)=J20,"RW",IF(MAX(H20,J20,L20,N20)=L20,"C","D")))) | S20: =IF(B20="","",IF(Q20="","Splits not loaded yet — run wcs_goalie_update.py (or no NHL history for this goalie).",IF(F20<Settings!$B$20,"SMALL SAMPLE — ","")&"Weakest vs "&IF(Q20="LW","left wingers",IF(Q20="RW","right wingers",IF(Q20="C","centers","defensemen (point shots)")))&" ("&TEXT(MIN(H20,J20,L20,N20),"+0.00;-0.00")&" GSAx/100). "&IF(MIN(H20,J20,L20,N20)<0,"Target: "&D20&" "&IF(Q20="D","D-men shooting from the point","players at "&Q20)&IF(IFERROR(INDEX('Team Outlook'!$G$13:$G$44,MATCH(D20,'Team Outlook'!$B$13:$B$44,0)),"")="",""," — best "&D20&" line tonight: "&IFERROR(INDEX('Team Outlook'!$G$13:$G$44,MATCH(D20,'Team Outlook'!$B$13:$B$44,0)),""))&".","No real hole — above expected at every position.")))
Q21: =IF(COUNT(H21,J21,L21,N21)<4,"",IF(MIN(H21,J21,L21,N21)=H21,"LW",IF(MIN(H21,J21,L21,N21)=J21,"RW",IF(MIN(H21,J21,L21,N21)=L21,"C","D")))) | R21: =IF(COUNT(H21,J21,L21,N21)<4,"",IF(MAX(H21,J21,L21,N21)=H21,"LW",IF(MAX(H21,J21,L21,N21)=J21,"RW",IF(MAX(H21,J21,L21,N21)=L21,"C","D")))) | S21: =IF(B21="","",IF(Q21="","Splits not loaded yet — run wcs_goalie_update.py (or no NHL history for this goalie).",IF(F21<Settings!$B$20,"SMALL SAMPLE — ","")&"Weakest vs "&IF(Q21="LW","left wingers",IF(Q21="RW","right wingers",IF(Q21="C","centers","defensemen (point shots)")))&" ("&TEXT(MIN(H21,J21,L21,N21),"+0.00;-0.00")&" GSAx/100). "&IF(MIN(H21,J21,L21,N21)<0,"Target: "&D21&" "&IF(Q21="D","D-men shooting from the point","players at "&Q21)&IF(IFERROR(INDEX('Team Outlook'!$G$13:$G$44,MATCH(D21,'Team Outlook'!$B$13:$B$44,0)),"")="",""," — best "&D21&" line tonight: "&IFERROR(INDEX('Team Outlook'!$G$13:$G$44,MATCH(D21,'Team Outlook'!$B$13:$B$44,0)),""))&".","No real hole — above expected at every position.")))
Q22: =IF(COUNT(H22,J22,L22,N22)<4,"",IF(MIN(H22,J22,L22,N22)=H22,"LW",IF(MIN(H22,J22,L22,N22)=J22,"RW",IF(MIN(H22,J22,L22,N22)=L22,"C","D")))) | R22: =IF(COUNT(H22,J22,L22,N22)<4,"",IF(MAX(H22,J22,L22,N22)=H22,"LW",IF(MAX(H22,J22,L22,N22)=J22,"RW",IF(MAX(H22,J22,L22,N22)=L22,"C","D")))) | S22: =IF(B22="","",IF(Q22="","Splits not loaded yet — run wcs_goalie_update.py (or no NHL history for this goalie).",IF(F22<Settings!$B$20,"SMALL SAMPLE — ","")&"Weakest vs "&IF(Q22="LW","left wingers",IF(Q22="RW","right wingers",IF(Q22="C","centers","defensemen (point shots)")))&" ("&TEXT(MIN(H22,J22,L22,N22),"+0.00;-0.00")&" GSAx/100). "&IF(MIN(H22,J22,L22,N22)<0,"Target: "&D22&" "&IF(Q22="D","D-men shooting from the point","players at "&Q22)&IF(IFERROR(INDEX('Team Outlook'!$G$13:$G$44,MATCH(D22,'Team Outlook'!$B$13:$B$44,0)),"")="",""," — best "&D22&" line tonight: "&IFERROR(INDEX('Team Outlook'!$G$13:$G$44,MATCH(D22,'Team Outlook'!$B$13:$B$44,0)),""))&".","No real hole — above expected at every position.")))
Q23: =IF(COUNT(H23,J23,L23,N23)<4,"",IF(MIN(H23,J23,L23,N23)=H23,"LW",IF(MIN(H23,J23,L23,N23)=J23,"RW",IF(MIN(H23,J23,L23,N23)=L23,"C","D")))) | R23: =IF(COUNT(H23,J23,L23,N23)<4,"",IF(MAX(H23,J23,L23,N23)=H23,"LW",IF(MAX(H23,J23,L23,N23)=J23,"RW",IF(MAX(H23,J23,L23,N23)=L23,"C","D")))) | S23: =IF(B23="","",IF(Q23="","Splits not loaded yet — run wcs_goalie_update.py (or no NHL history for this goalie).",IF(F23<Settings!$B$20,"SMALL SAMPLE — ","")&"Weakest vs "&IF(Q23="LW","left wingers",IF(Q23="RW","right wingers",IF(Q23="C","centers","defensemen (point shots)")))&" ("&TEXT(MIN(H23,J23,L23,N23),"+0.00;-0.00")&" GSAx/100). "&IF(MIN(H23,J23,L23,N23)<0,"Target: "&D23&" "&IF(Q23="D","D-men shooting from the point","players at "&Q23)&IF(IFERROR(INDEX('Team Outlook'!$G$13:$G$44,MATCH(D23,'Team Outlook'!$B$13:$B$44,0)),"")="",""," — best "&D23&" line tonight: "&IFERROR(INDEX('Team Outlook'!$G$13:$G$44,MATCH(D23,'Team Outlook'!$B$13:$B$44,0)),""))&".","No real hole — above expected at every position.")))
... Q37: =IF(COUNT(H37,J37,L37,N37)<4,"",IF(MIN(H37,J37,L37,N37)=H37,"LW",IF(MIN(H37,J37,L37,N37)=J37,"RW",IF(MIN(H37,J37,L37,N37)=L37,"C","D")))) | R37: =IF(COUNT(H37,J37,L37,N37)<4,"",IF(MAX(H37,J37,L37,N37)=H37,"LW",IF(MAX(H37,J37,L37,N37)=J37,"RW",IF(MAX(H37,J37,L37,N37)=L37,"C","D")))) | S37: =IF(B37="","",IF(Q37="","Splits not loaded yet — run wcs_goalie_update.py (or no NHL history for this goalie).",IF(F37<Settings!$B$20,"SMALL SAMPLE — ","")&"Weakest vs "&IF(Q37="LW","left wingers",IF(Q37="RW","right wingers",IF(Q37="C","centers","defensemen (point shots)")))&" ("&TEXT(MIN(H37,J37,L37,N37),"+0.00;-0.00")&" GSAx/100). "&IF(MIN(H37,J37,L37,N37)<0,"Target: "&D37&" "&IF(Q37="D","D-men shooting from the point","players at "&Q37)&IF(IFERROR(INDEX('Team Outlook'!$G$13:$G$44,MATCH(D37,'Team Outlook'!$B$13:$B$44,0)),"")="",""," — best "&D37&" line tonight: "&IFERROR(INDEX('Team Outlook'!$G$13:$G$44,MATCH(D37,'Team Outlook'!$B$13:$B$44,0)),""))&".","No real hole — above expected at every position.")))

Sheet Line Stats
A1: WCS ANALYTICS — NHL LINE STATS | Source: Daily Faceoff DFS Line Stats (5v5)
A2: HOW TO UPDATE: paste tonight's Daily Faceoff Line Stats into the BLUE columns (A–R), one row per line, all 4 lines of a team together. Type each line's opponent in column B. Columns S–V calculate automatically. GREEN = good, RED = bad, GOLD row = HIGH scoring chance.
A3: Slate date: | B3: 2026-10-07
A4: LINE | E4: OFFENCE (higher = better) | K4: DEFENCE (lower 'against' = better) | Q4: SHARE % | S4: WCS SCORING MODEL (auto)
A5: Team | B5: Opponent | C5: Line | D5: TOI | E5: CF/60 | F5: GF/60 | G5: xGF/60 | H5: SCF/60 | I5: HDCF/60 | J5: O-Score | K5: CA/60 | L5: GA/60 | M5: xGA/60 | N5: SCA/60 | O5: HDCA/60 | P5: D-Score | Q5: CF% | R5: xGF% | S5: Scoring Index | T5: Tier | U5: Slate Rank | V5: Analysis / Comment | W5: TeamKey | X5: SortKey | Y5: WtIdx | Z5: WtTOI
A6: Capitals | B6: Penguins | C6: FL1 | D6: 16 | E6: 53 | F6: 3.4 | G6: 2.5 | H6: 28.1 | I6: 8.4 | J6: 25 | K6: 57.5 | L6: 3.1 | M6: 2.5 | N6: 24 | O6: 10.1 | P6: 66.7 | Q6: 0.479 | R6: 0.503 | S6: =IF(A6="","",IF(AND(G6=0,H6=0,I6=0),"",ROUND(100*(Settings!$B$9*(Settings!$B$5*IFERROR(PERCENTRANK($G$6:$G$69,G6),0.5)+Settings!$B$6*IFERROR(PERCENTRANK($I$6:$I$69,I6),0.5)+Settings!$B$7*IFERROR(PERCENTRANK($H$6:$H$69,H6),0.5)+Settings!$B$8*IFERROR(PERCENTRANK($E$6:$E$69,E6),0.5))+Settings!$B$10*(1-IFERROR(AVERAGEIF($A$6:$A$69,B6,$P$6:$P$69)/100,0.5))),1))) -> 32.4 | T6: =IF(A6="","",IF(S6="","LOW SAMPLE",IF(OR(R6>=Settings!$B$18,R6<=1-Settings!$B$18,Q6>=Settings!$B$19,Q6<=1-Settings!$B$19),"CAUTION",IF(S6>=Settings!$B$11,"HIGH",IF(S6>=Settings!$B$12,"MEDIUM","LOW"))))) -> LOW | U6: =IF(X6="","",RANK(X6,$X$6:$X$69)) -> 17 | V6: =IF(A6="","",IF(T6="LOW SAMPLE","Not enough data — this combination has barely played together. Ignore tonight.",IF(T6="CAUTION","CAUTION: extreme CF%/xGF% split — likely a tiny sample, numbers unreliable. Left out of Top 3 and team score. ",T6&" scoring chance. ")&IF(F6-G6>=Settings!$B$13,"Finishing above its xG — regression risk. ",IF(G6-F6>=Settings!$B$13,"Creating more than it scores — due for goals. ","Goals in line with chances. "))&IF(I6>=LARGE($I$6:$I$69,3),"Top-3 high-danger creator on the slate. ","")&"Faces "&B6&" (opp avg D-Score "&TEXT(IFERROR(AVERAGEIF($A$6:$A$69,B6,$P$6:$P$69),0),"0")&").")) -> LOW scoring chance. Goals in line with chances. Faces Penguins (opp avg D-Score 45). | W6: =IF(A6="","",IF(COUNTIF($A$6:A6,A6)=1,MAX($W$5:W5)+1,"")) -> 1 | X6: =IF(OR(S6="",T6="CAUTION"),"",S6+ROW()/1000000) -> 32.400006 | Y6: =IF(OR(S6="",T6="CAUTION"),0,S6*D6) -> 518.4 | Z6: =IF(OR(S6="",T6="CAUTION"),0,D6) -> 16
A7: Capitals | B7: Penguins | C7: FL2 | D7: 14.3 | E7: 64.2 | F7: 3.3 | G7: 3.3 | H7: 31.4 | I7: 14.7 | J7: 75 | K7: 59.5 | L7: 1.9 | M7: 3 | N7: 29.6 | O7: 14.1 | P7: 29.2 | Q7: 0.519 | R7: 0.526 | S7: =IF(A7="","",IF(AND(G7=0,H7=0,I7=0),"",ROUND(100*(Settings!$B$9*(Settings!$B$5*IFERROR(PERCENTRANK($G$6:$G$69,G7),0.5)+Settings!$B$6*IFERROR(PERCENTRANK($I$6:$I$69,I7),0.5)+Settings!$B$7*IFERROR(PERCENTRANK($H$6:$H$69,H7),0.5)+Settings!$B$8*IFERROR(PERCENTRANK($E$6:$E$69,E7),0.5))+Settings!$B$10*(1-IFERROR(AVERAGEIF($A$6:$A$69,B7,$P$6:$P$69)/100,0.5))),1))) -> 66.3 | T7: =IF(A7="","",IF(S7="","LOW SAMPLE",IF(OR(R7>=Settings!$B$18,R7<=1-Settings!$B$18,Q7>=Settings!$B$19,Q7<=1-Settings!$B$19),"CAUTION",IF(S7>=Settings!$B$11,"HIGH",IF(S7>=Settings!$B$12,"MEDIUM","LOW"))))) -> HIGH | U7: =IF(X7="","",RANK(X7,$X$6:$X$69)) -> 5 | V7: =IF(A7="","",IF(T7="LOW SAMPLE","Not enough data — this combination has barely played together. Ignore tonight.",IF(T7="CAUTION","CAUTION: extreme CF%/xGF% split — likely a tiny sample, numbers unreliable. Left out of Top 3 and team score. ",T7&" scoring chance. ")&IF(F7-G7>=Settings!$B$13,"Finishing above its xG — regression risk. ",IF(G7-F7>=Settings!$B$13,"Creating more than it scores — due for goals. ","Goals in line with chances. "))&IF(I7>=LARGE($I$6:$I$69,3),"Top-3 high-danger creator on the slate. ","")&"Faces "&B7&" (opp avg D-Score "&TEXT(IFERROR(AVERAGEIF($A$6:$A$69,B7,$P$6:$P$69),0),"0")&").")) -> HIGH scoring chance. Goals in line with chances. Faces Penguins (opp avg D-Score 45). | W7: =IF(A7="","",IF(COUNTIF($A$6:A7,A7)=1,MAX($W$5:W6)+1,"")) | X7: =IF(OR(S7="",T7="CAUTION"),"",S7+ROW()/1000000) -> 66.300007 | Y7: =IF(OR(S7="",T7="CAUTION"),0,S7*D7) -> 948.09 | Z7: =IF(OR(S7="",T7="CAUTION"),0,D7) -> 14.3
A8: Capitals | B8: Penguins | C8: FL3 | D8: 13.5 | E8: 53.8 | F8: 2.7 | G8: 2.8 | H8: 33.6 | I8: 12.1 | J8: 50 | K8: 52.4 | L8: 1.3 | M8: 2.8 | N8: 25.5 | O8: 13.4 | P8: 70.8 | Q8: 0.506 | R8: 0.501 | S8: =IF(A8="","",IF(AND(G8=0,H8=0,I8=0),"",ROUND(100*(Settings!$B$9*(Settings!$B$5*IFERROR(PERCENTRANK($G$6:$G$69,G8),0.5)+Settings!$B$6*IFERROR(PERCENTRANK($I$6:$I$69,I8),0.5)+Settings!$B$7*IFERROR(PERCENTRANK($H$6:$H$69,H8),0.5)+Settings!$B$8*IFERROR(PERCENTRANK($E$6:$E$69,E8),0.5))+Settings!$B$10*(1-IFERROR(AVERAGEIF($A$6:$A$69,B8,$P$6:$P$69)/100,0.5))),1))) -> 48.1 | T8: =IF(A8="","",IF(S8="","LOW SAMPLE",IF(OR(R8>=Settings!$B$18,R8<=1-Settings!$B$18,Q8>=Settings!$B$19,Q8<=1-Settings!$B$19),"CAUTION",IF(S8>=Settings!$B$11,"HIGH",IF(S8>=Settings!$B$12,"MEDIUM","LOW"))))) -> MEDIUM | U8: =IF(X8="","",RANK(X8,$X$6:$X$69)) -> 11 | V8: =IF(A8="","",IF(T8="LOW SAMPLE","Not enough data — this combination has barely played together. Ignore tonight.",IF(T8="CAUTION","CAUTION: extreme CF%/xGF% split — likely a tiny sample, numbers unreliable. Left out of Top 3 and team score. ",T8&" scoring chance. ")&IF(F8-G8>=Settings!$B$13,"Finishing above its xG — regression risk. ",IF(G8-F8>=Settings!$B$13,"Creating more than it scores — due for goals. ","Goals in line with chances. "))&IF(I8>=LARGE($I$6:$I$69,3),"Top-3 high-danger creator on the slate. ","")&"Faces "&B8&" (opp avg D-Score "&TEXT(IFERROR(AVERAGEIF($A$6:$A$69,B8,$P$6:$P$69),0),"0")&").")) -> MEDIUM scoring chance. Goals in line with chances. Faces Penguins (opp avg D-Score 45). | W8: =IF(A8="","",IF(COUNTIF($A$6:A8,A8)=1,MAX($W$5:W7)+1,"")) | X8: =IF(OR(S8="",T8="CAUTION"),"",S8+ROW()/1000000) -> 48.100008 | Y8: =IF(OR(S8="",T8="CAUTION"),0,S8*D8) -> 649.35 | Z8: =IF(OR(S8="",T8="CAUTION"),0,D8) -> 13.5
A9: Capitals | B9: Penguins | C9: FL4 | D9: 12.3 | E9: 49 | F9: 4.4 | G9: 2.2 | H9: 22.4 | I9: 9.5 | J9: 12.5 | K9: 56.2 | L9: 1.9 | M9: 2.8 | N9: 26.6 | O9: 13.9 | P9: 41.7 | Q9: 0.466 | R9: 0.433 | S9: =IF(A9="","",IF(AND(G9=0,H9=0,I9=0),"",ROUND(100*(Settings!$B$9*(Settings!$B$5*IFERROR(PERCENTRANK($G$6:$G$69,G9),0.5)+Settings!$B$6*IFERROR(PERCENTRANK($I$6:$I$69,I9),0.5)+Settings!$B$7*IFERROR(PERCENTRANK($H$6:$H$69,H9),0.5)+Settings!$B$8*IFERROR(PERCENTRANK($E$6:$E$69,E9),0.5))+Settings!$B$10*(1-IFERROR(AVERAGEIF($A$6:$A$69,B9,$P$6:$P$69)/100,0.5))),1))) -> 27.9 | T9: =IF(A9="","",IF(S9="","LOW SAMPLE",IF(OR(R9>=Settings!$B$18,R9<=1-Settings!$B$18,Q9>=Settings!$B$19,Q9<=1-Settings!$B$19),"CAUTION",IF(S9>=Settings!$B$11,"HIGH",IF(S9>=Settings!$B$12,"MEDIUM","LOW"))))) -> LOW | U9: =IF(X9="","",RANK(X9,$X$6:$X$69)) -> 18 | V9: =IF(A9="","",IF(T9="LOW SAMPLE","Not enough data — this combination has barely played together. Ignore tonight.",IF(T9="CAUTION","CAUTION: extreme CF%/xGF% split — likely a tiny sample, numbers unreliable. Left out of Top 3 and team score. ",T9&" scoring chance. ")&IF(F9-G9>=Settings!$B$13,"Finishing above its xG — regression risk. ",IF(G9-F9>=Settings!$B$13,"Creating more than it scores — due for goals. ","Goals in line with chances. "))&IF(I9>=LARGE($I$6:$I$69,3),"Top-3 high-danger creator on the slate. ","")&"Faces "&B9&" (opp avg D-Score "&TEXT(IFERROR(AVERAGEIF($A$6:$A$69,B9,$P$6:$P$69),0),"0")&").")) -> LOW scoring chance. Finishing above its xG — regression risk. Faces Penguins (opp avg D-Score 45). | W9: =IF(A9="","",IF(COUNTIF($A$6:A9,A9)=1,MAX($W$5:W8)+1,"")) | X9: =IF(OR(S9="",T9="CAUTION"),"",S9+ROW()/1000000) -> 27.900009 | Y9: =IF(OR(S9="",T9="CAUTION"),0,S9*D9) -> 343.17 | Z9: =IF(OR(S9="",T9="CAUTION"),0,D9) -> 12.3
A10: Penguins | B10: Capitals | C10: FL1 | D10: 16.1 | E10: 62 | F10: 3.1 | G10: 3.3 | H10: 31.5 | I10: 14.7 | J10: 70.8 | K10: 60.8 | L10: 2.4 | M10: 2.9 | N10: 30.4 | O10: 13.5 | P10: 25 | Q10: 0.505 | R10: 0.533 | S10: =IF(A10="","",IF(AND(G10=0,H10=0,I10=0),"",ROUND(100*(Settings!$B$9*(Settings!$B$5*IFERROR(PERCENTRANK($G$6:$G$69,G10),0.5)+Settings!$B$6*IFERROR(PERCENTRANK($I$6:$I$69,I10),0.5)+Settings!$B$7*IFERROR(PERCENTRANK($H$6:$H$69,H10),0.5)+Settings!$B$8*IFERROR(PERCENTRANK($E$6:$E$69,E10),0.5))+Settings!$B$10*(1-IFERROR(AVERAGEIF($A$6:$A$69,B10,$P$6:$P$69)/100,0.5))),1))) -> 64.3 | T10: =IF(A10="","",IF(S10="","LOW SAMPLE",IF(OR(R10>=Settings!$B$18,R10<=1-Settings!$B$18,Q10>=Settings!$B$19,Q10<=1-Settings!$B$19),"CAUTION",IF(S10>=Settings!$B$11,"HIGH",IF(S10>=Settings!$B$12,"MEDIUM","LOW"))))) -> HIGH | U10: =IF(X10="","",RANK(X10,$X$6:$X$69)) -> 6 | V10: =IF(A10="","",IF(T10="LOW SAMPLE","Not enough data — this combination has barely played together. Ignore tonight.",IF(T10="CAUTION","CAUTION: extreme CF%/xGF% split — likely a tiny sample, numbers unreliable. Left out of Top 3 and team score. ",T10&" scoring chance. ")&IF(F10-G10>=Settings!$B$13,"Finishing above its xG — regression risk. ",IF(G10-F10>=Settings!$B$13,"Creating more than it scores — due for goals. ","Goals in line with chances. "))&IF(I10>=LARGE($I$6:$I$69,3),"Top-3 high-danger creator on the slate. ","")&"Faces "&B10&" (opp avg D-Score "&TEXT(IFERROR(AVERAGEIF($A$6:$A$69,B10,$P$6:$P$69),0),"0")&").")) -> HIGH scoring chance. Goals in line with chances. Faces Capitals (opp avg D-Score 52). | W10: =IF(A10="","",IF(COUNTIF($A$6:A10,A10)=1,MAX($W$5:W9)+1,"")) -> 2 | X10: =IF(OR(S10="",T10="CAUTION"),"",S10+ROW()/1000000) -> 64.30001 | Y10: =IF(OR(S10="",T10="CAUTION"),0,S10*D10) -> 1035.23 | Z10: =IF(OR(S10="",T10="CAUTION"),0,D10) -> 16.1
A11: Penguins | B11: Capitals | C11: FL2 | D11: 16.5 | E11: 58.1 | F11: 3.8 | G11: 3.4 | H11: 34 | I11: 16.1 | J11: 79.2 | K11: 61.2 | L11: 2.6 | M11: 3.3 | N11: 30.7 | O11: 14.7 | P11: 16.7 | Q11: 0.487 | R11: 0.508 | S11: =IF(A11="","",IF(AND(G11=0,H11=0,I11=0),"",ROUND(100*(Settings!$B$9*(Settings!$B$5*IFERROR(PERCENTRANK($G$6:$G$69,G11),0.5)+Settings!$B$6*IFERROR(PERCENTRANK($I$6:$I$69,I11),0.5)+Settings!$B$7*IFERROR(PERCENTRANK($H$6:$H$69,H11),0.5)+Settings!$B$8*IFERROR(PERCENTRANK($E$6:$E$69,E11),0.5))+Settings!$B$10*(1-IFERROR(AVERAGEIF($A$6:$A$69,B11,$P$6:$P$69)/100,0.5))),1))) -> 71.8 | T11: =IF(A11="","",IF(S11="","LOW SAMPLE",IF(OR(R11>=Settings!$B$18,R11<=1-Settings!$B$18,Q11>=Settings!$B$19,Q11<=1-Settings!$B$19),"CAUTION",IF(S11>=Settings!$B$11,"HIGH",IF(S11>=Settings!$B$12,"MEDIUM","LOW"))))) -> HIGH | U11: =IF(X11="","",RANK(X11,$X$6:$X$69)) -> 3 | V11: =IF(A11="","",IF(T11="LOW SAMPLE","Not enough data — this combination has barely played together. Ignore tonight.",IF(T11="CAUTION","CAUTION: extreme CF%/xGF% split — likely a tiny sample, numbers unreliable. Left out of Top 3 and team score. ",T11&" scoring chance. ")&IF(F11-G11>=Settings!$B$13,"Finishing above its xG — regression risk. ",IF(G11-F11>=Settings!$B$13,"Creating more than it scores — due for goals. ","Goals in line with chances. "))&IF(I11>=LARGE($I$6:$I$69,3),"Top-3 high-danger creator on the slate. ","")&"Faces "&B11&" (opp avg D-Score "&TEXT(IFERROR(AVERAGEIF($A$6:$A$69,B11,$P$6:$P$69),0),"0")&").")) -> HIGH scoring chance. Goals in line with chances. Top-3 high-danger creator on the slate. Faces Capitals (opp avg D-Score 52). | W11: =IF(A11="","",IF(COUNTIF($A$6:A11,A11)=1,MAX($W$5:W10)+1,"")) | X11: =IF(OR(S11="",T11="CAUTION"),"",S11+ROW()/1000000) -> 71.800011 | Y11: =IF(OR(S11="",T11="CAUTION"),0,S11*D11) -> 1184.7 | Z11: =IF(OR(S11="",T11="CAUTION"),0,D11) -> 16.5
A12: Penguins | B12: Capitals | C12: FL3 | D12: 12.3 | E12: 26.1 | F12: 0 | G12: 0 | H12: 0 | I12: 0 | J12: 37.5 | K12: 52.2 | L12: 0 | M12: 1.1 | N12: 26.1 | O12: 0 | P12: 58.3 | Q12: 0.333 | R12: 0 | S12: =IF(A12="","",IF(AND(G12=0,H12=0,I12=0),"",ROUND(100*(Settings!$B$9*(Settings!$B$5*IFERROR(PERCENTRANK($G$6:$G$69,G12),0.5)+Settings!$B$6*IFERROR(PERCENTRANK($I$6:$I$69,I12),0.5)+Settings!$B$7*IFERROR(PERCENTRANK($H$6:$H$69,H12),0.5)+Settings!$B$8*IFERROR(PERCENTRANK($E$6:$E$69,E12),0.5))+Settings!$B$10*(1-IFERROR(AVERAGEIF($A$6:$A$69,B12,$P$6:$P$69)/100,0.5))),1))) | T12: =IF(A12="","",IF(S12="","LOW SAMPLE",IF(OR(R12>=Settings!$B$18,R12<=1-Settings!$B$18,Q12>=Settings!$B$19,Q12<=1-Settings!$B$19),"CAUTION",IF(S12>=Settings!$B$11,"HIGH",IF(S12>=Settings!$B$12,"MEDIUM","LOW"))))) -> LOW SAMPLE | U12: =IF(X12="","",RANK(X12,$X$6:$X$69)) | V12: =IF(A12="","",IF(T12="LOW SAMPLE","Not enough data — this combination has barely played together. Ignore tonight.",IF(T12="CAUTION","CAUTION: extreme CF%/xGF% split — likely a tiny sample, numbers unreliable. Left out of Top 3 and team score. ",T12&" scoring chance. ")&IF(F12-G12>=Settings!$B$13,"Finishing above its xG — regression risk. ",IF(G12-F12>=Settings!$B$13,"Creating more than it scores — due for goals. ","Goals in line with chances. "))&IF(I12>=LARGE($I$6:$I$69,3),"Top-3 high-danger creator on the slate. ","")&"Faces "&B12&" (opp avg D-Score "&TEXT(IFERROR(AVERAGEIF($A$6:$A$69,B12,$P$6:$P$69),0),"0")&").")) -> Not enough data — this combination has barely played together. Ignore tonight. | W12: =IF(A12="","",IF(COUNTIF($A$6:A12,A12)=1,MAX($W$5:W11)+1,"")) | X12: =IF(OR(S12="",T12="CAUTION"),"",S12+ROW()/1000000) | Y12: =IF(OR(S12="",T12="CAUTION"),0,S12*D12) -> 0 | Z12: =IF(OR(S12="",T12="CAUTION"),0,D12) -> 0
A13: Penguins | B13: Capitals | C13: FL4 | D13: 10.9 | E13: 61.7 | F13: 2.3 | G13: 2.7 | H13: 29.2 | I13: 12.2 | J13: 54.2 | K13: 53.1 | L13: 2 | M13: 2.4 | N13: 23.7 | O13: 11.1 | P13: 79.2 | Q13: 0.538 | R13: 0.531 | S13: =IF(A13="","",IF(AND(G13=0,H13=0,I13=0),"",ROUND(100*(Settings!$B$9*(Settings!$B$5*IFERROR(PERCENTRANK($G$6:$G$69,G13),0.5)+Settings!$B$6*IFERROR(PERCENTRANK($I$6:$I$69,I13),0.5)+Settings!$B$7*IFERROR(PERCENTRANK($H$6:$H$69,H13),0.5)+Settings!$B$8*IFERROR(PERCENTRANK($E$6:$E$69,E13),0.5))+Settings!$B$10*(1-IFERROR(AVERAGEIF($A$6:$A$69,B13,$P$6:$P$69)/100,0.5))),1))) -> 43.7 | T13: =IF(A13="","",IF(S13="","LOW SAMPLE",IF(OR(R13>=Settings!$B$18,R13<=1-Settings!$B$18,Q13>=Settings!$B$19,Q13<=1-Settings!$B$19),"CAUTION",IF(S13>=Settings!$B$11,"HIGH",IF(S13>=Settings!$B$12,"MEDIUM","LOW"))))) -> LOW | U13: =IF(X13="","",RANK(X13,$X$6:$X$69)) -> 13 | V13: =IF(A13="","",IF(T13="LOW SAMPLE","Not enough data — this combination has barely played together. Ignore tonight.",IF(T13="CAUTION","CAUTION: extreme CF%/xGF% split — likely a tiny sample, numbers unreliable. Left out of Top 3 and team score. ",T13&" scoring chance. ")&IF(F13-G13>=Settings!$B$13,"Finishing above its xG — regression risk. ",IF(G13-F13>=Settings!$B$13,"Creating more than it scores — due for goals. ","Goals in line with chances. "))&IF(I13>=LARGE($I$6:$I$69,3),"Top-3 high-danger creator on the slate. ","")&"Faces "&B13&" (opp avg D-Score "&TEXT(IFERROR(AVERAGEIF($A$6:$A$69,B13,$P$6:$P$69),0),"0")&").")) -> LOW scoring chance. Goals in line with chances. Faces Capitals (opp avg D-Score 52). | W13: =IF(A13="","",IF(COUNTIF($A$6:A13,A13)=1,MAX($W$5:W12)+1,"")) | X13: =IF(OR(S13="",T13="CAUTION"),"",S13+ROW()/1000000) -> 43.700013 | Y13: =IF(OR(S13="",T13="CAUTION"),0,S13*D13) -> 476.33 | Z13: =IF(OR(S13="",T13="CAUTION"),0,D13) -> 10.9
A14: Ducks | B14: Oilers | C14: FL1 | D14: 16 | E14: 71 | F14: 4 | G14: 3 | H14: 31.3 | I14: 11.7 | J14: 62.5 | K14: 56 | L14: 2.9 | M14: 2.8 | N14: 30.6 | O14: 15.2 | P14: 20.8 | Q14: 0.559 | R14: 0.519 | S14: =IF(A14="","",IF(AND(G14=0,H14=0,I14=0),"",ROUND(100*(Settings!$B$9*(Settings!$B$5*IFERROR(PERCENTRANK($G$6:$G$69,G14),0.5)+Settings!$B$6*IFERROR(PERCENTRANK($I$6:$I$69,I14),0.5)+Settings!$B$7*IFERROR(PERCENTRANK($H$6:$H$69,H14),0.5)+Settings!$B$8*IFERROR(PERCENTRANK($E$6:$E$69,E14),0.5))+Settings!$B$10*(1-IFERROR(AVERAGEIF($A$6:$A$69,B14,$P$6:$P$69)/100,0.5))),1))) -> 43.6 | T14: =IF(A14="","",IF(S14="","LOW SAMPLE",IF(OR(R14>=Settings!$B$18,R14<=1-Settings!$B$18,Q14>=Settings!$B$19,Q14<=1-Settings!$B$19),"CAUTION",IF(S14>=Settings!$B$11,"HIGH",IF(S14>=Settings!$B$12,"MEDIUM","LOW"))))) -> LOW | U14: =IF(X14="","",RANK(X14,$X$6:$X$69)) -> 14 | V14: =IF(A14="","",IF(T14="LOW SAMPLE","Not enough data — this combination has barely played together. Ignore tonight.",IF(T14="CAUTION","CAUTION: extreme CF%/xGF% split — likely a tiny sample, numbers unreliable. Left out of Top 3 and team score. ",T14&" scoring chance. ")&IF(F14-G14>=Settings!$B$13,"Finishing above its xG — regression risk. ",IF(G14-F14>=Settings!$B$13,"Creating more than it scores — due for goals. ","Goals in line with chances. "))&IF(I14>=LARGE($I$6:$I$69,3),"Top-3 high-danger creator on the slate. ","")&"Faces "&B14&" (opp avg D-Score "&TEXT(IFERROR(AVERAGEIF($A$6:$A$69,B14,$P$6:$P$69),0),"0")&").")) -> LOW scoring chance. Finishing above its xG — regression risk. Faces Oilers (opp avg D-Score 75). | W14: =IF(A14="","",IF(COUNTIF($A$6:A14,A14)=1,MAX($W$5:W13)+1,"")) -> 3 | X14: =IF(OR(S14="",T14="CAUTION"),"",S14+ROW()/1000000) -> 43.600014 | Y14: =IF(OR(S14="",T14="CAUTION"),0,S14*D14) -> 697.6 | Z14: =IF(OR(S14="",T14="CAUTION"),0,D14) -> 16
A15: Ducks | B15: Oilers | C15: FL2 | D15: 16.5 | E15: 59.9 | F15: 2.4 | G15: 3.1 | H15: 29.8 | I15: 14.2 | J15: 58.3 | K15: 53.7 | L15: 1.9 | M15: 2.4 | N15: 24.8 | O15: 9.9 | P15: 83.3 | Q15: 0.528 | R15: 0.563 | S15: =IF(A15="","",IF(AND(G15=0,H15=0,I15=0),"",ROUND(100*(Settings!$B$9*(Settings!$B$5*IFERROR(PERCENTRANK($G$6:$G$69,G15),0.5)+Settings!$B$6*IFERROR(PERCENTRANK($I$6:$I$69,I15),0.5)+Settings!$B$7*IFERROR(PERCENTRANK($H$6:$H$69,H15),0.5)+Settings!$B$8*IFERROR(PERCENTRANK($E$6:$E$69,E15),0.5))+Settings!$B$10*(1-IFERROR(AVERAGEIF($A$6:$A$69,B15,$P$6:$P$69)/100,0.5))),1))) -> 48 | T15: =IF(A15="","",IF(S15="","LOW SAMPLE",IF(OR(R15>=Settings!$B$18,R15<=1-Settings!$B$18,Q15>=Settings!$B$19,Q15<=1-Settings!$B$19),"CAUTION",IF(S15>=Settings!$B$11,"HIGH",IF(S15>=Settings!$B$12,"MEDIUM","LOW"))))) -> MEDIUM | U15: =IF(X15="","",RANK(X15,$X$6:$X$69)) -> 12 | V15: =IF(A15="","",IF(T15="LOW SAMPLE","Not enough data — this combination has barely played together. Ignore tonight.",IF(T15="CAUTION","CAUTION: extreme CF%/xGF% split — likely a tiny sample, numbers unreliable. Left out of Top 3 and team score. ",T15&" scoring chance. ")&IF(F15-G15>=Settings!$B$13,"Finishing above its xG — regression risk. ",IF(G15-F15>=Settings!$B$13,"Creating more than it scores — due for goals. ","Goals in line with chances. "))&IF(I15>=LARGE($I$6:$I$69,3),"Top-3 high-danger creator on the slate. ","")&"Faces "&B15&" (opp avg D-Score "&TEXT(IFERROR(AVERAGEIF($A$6:$A$69,B15,$P$6:$P$69),0),"0")&").")) -> MEDIUM scoring chance. Goals in line with chances. Faces Oilers (opp avg D-Score 75). | W15: =IF(A15="","",IF(COUNTIF($A$6:A15,A15)=1,MAX($W$5:W14)+1,"")) | X15: =IF(OR(S15="",T15="CAUTION"),"",S15+ROW()/1000000) -> 48.000015 | Y15: =IF(OR(S15="",T15="CAUTION"),0,S15*D15) -> 792 | Z15: =IF(OR(S15="",T15="CAUTION"),0,D15) -> 16.5
A16: Ducks | B16: Oilers | C16: FL3 | D16: 13.5 | E16: 53.3 | F16: 1.2 | G16: 2.3 | H16: 23 | I16: 9.3 | J16: 20.8 | K16: 55.7 | L16: 1.6 | M16: 2.2 | N16: 27 | O16: 8.9 | P16: 87.5 | Q16: 0.489 | R16: 0.516 | S16: =IF(A16="","",IF(AND(G16=0,H16=0,I16=0),"",ROUND(100*(Settings!$B$9*(Settings!$B$5*IFERROR(PERCENTRANK($G$6:$G$69,G16),0.5)+Settings!$B$6*IFERROR(PERCENTRANK($I$6:$I$69,I16),0.5)+Settings!$B$7*IFERROR(PERCENTRANK($H$6:$H$69,H16),0.5)+Settings!$B$8*IFERROR(PERCENTRANK($E$6:$E$69,E16),0.5))+Settings!$B$10*(1-IFERROR(AVERAGEIF($A$6:$A$69,B16,$P$6:$P$69)/100,0.5))),1))) -> 20.1 | T16: =IF(A16="","",IF(S16="","LOW SAMPLE",IF(OR(R16>=Settings!$B$18,R16<=1-Settings!$B$18,Q16>=Settings!$B$19,Q16<=1-Settings!$B$19),"CAUTION",IF(S16>=Settings!$B$11,"HIGH",IF(S16>=Settings!$B$12,"MEDIUM","LOW"))))) -> LOW | U16: =IF(X16="","",RANK(X16,$X$6:$X$69)) -> 20 | V16: =IF(A16="","",IF(T16="LOW SAMPLE","Not enough data — this combination has barely played together. Ignore tonight.",IF(T16="CAUTION","CAUTION: extreme CF%/xGF% split — likely a tiny sample, numbers unreliable. Left out of Top 3 and team score. ",T16&" scoring chance. ")&IF(F16-G16>=Settings!$B$13,"Finishing above its xG — regression risk. ",IF(G16-F16>=Settings!$B$13,"Creating more than it scores — due for goals. ","Goals in line with chances. "))&IF(I16>=LARGE($I$6:$I$69,3),"Top-3 high-danger creator on the slate. ","")&"Faces "&B16&" (opp avg D-Score "&TEXT(IFERROR(AVERAGEIF($A$6:$A$69,B16,$P$6:$P$69),0),"0")&").")) -> LOW scoring chance. Creating more than it scores — due for goals. Faces Oilers (opp avg D-Score 75). | W16: =IF(A16="","",IF(COUNTIF($A$6:A16,A16)=1,MAX($W$5:W15)+1,"")) | X16: =IF(OR(S16="",T16="CAUTION"),"",S16+ROW()/1000000) -> 20.100016 | Y16: =IF(OR(S16="",T16="CAUTION"),0,S16*D16) -> 271.35 | Z16: =IF(OR(S16="",T16="CAUTION"),0,D16) -> 13.5
